Workbook
Name B78X: #REF!

Sheet LEBL_10AUG2025
A1: ARCID | B1: ATYP | C1: ADEP | D1: ADES | E1: RM | F1: ARF | G1: ETD | H1: TT | I1: ETA | J1: Aircraft category | K1: Seats | L1: Flight_time(ETA-ETD) | M1: Arrivalf_time | N1: Average Speed(km/h) | O1: Category | Q1: Flight_Distance (km) | R1: Flight Airline | S1: ECAC
A2: RYR404A | B2: B738 | C2: LPPR | D2: LEBL | E2: EIDCJ | F2: 380 | G2: 0.95138889 | H2: 15 | I2: 0.0034722222 | J2: {=XLOOKUP(B2,cat!B:B,cat!C:C)} -> D | K2: {=XLOOKUP(B2,cat!B:B,cat!D:D)} -> 184 | L2: =mod(I2-G2,1) -> 0.052083333 | M2: =IF($D2="LEBL", IF($L2-(18.3/1440)-($H2/1440)<0, $L2-($H2/1440), $L2-(18.3/1440)-($H2/1440) ), "") -> 0.028958333 | N2: 910 | O2: A | Q2: =IFERROR(M2*24*XLOOKUP(J2,$O$2:$O$7,$N$2:$N$7), "") -> 576.85 | R2: =LEFT(A2,3) -> RYR | S2: =IF($D2="LEBL", IF(COUNTIF('Paises ECAC'!B:B, C2)>0, "ECAC","NO ECAC"), "") -> ECAC
A3: AEE713 | B3: A20N | C3: LEBL | D3: LGAV | E3: SXNEB | F3: 390 | G3: 0.013194444 | H3: 9 | I3: 0.11458333 | J3: {=XLOOKUP(B3,cat!B:B,cat!C:C)} -> D | K3: {=XLOOKUP(B3,cat!B:B,cat!D:D)} -> 180 | L3: =mod(I3-G3,1) -> 0.10138889 | M3: =IF($D3="LEBL", IF($L3-(18.3/1440)-($H3/1440)<0, $L3-($H3/1440), $L3-(18.3/1440)-($H3/1440) ), "") | N3: 900 | O3: B | Q3: =IFERROR(M3*24*XLOOKUP(J3,$O$2:$O$7,$N$2:$N$7), "") -> 0 | R3: =LEFT(A3,3) -> AEE | S3: =IF($D3="LEBL", IF(COUNTIF('Paises ECAC'!B:B, C3)>0, "ECAC","NO ECAC"), "")
A4: VLG7575 | B4: A320 | C4: GBYD | D4: LEBL | E4: ECLVV | F4: 380 | G4: 0.85069444 | H4: 10 | I4: 0.03125 | J4: {=XLOOKUP(B4,cat!B:B,cat!C:C)} -> D | K4: {=XLOOKUP(B4,cat!B:B,cat!D:D)} -> 173 | L4: =mod(I4-G4,1) -> 0.18055556 | M4: =IF($D4="LEBL", IF($L4-(18.3/1440)-($H4/1440)<0, $L4-($H4/1440), $L4-(18.3/1440)-($H4/1440) ), "") -> 0.16090278 | N4: 870 | O4: C | Q4: =IFERROR(M4*24*XLOOKUP(J4,$O$2:$O$7,$N$2:$N$7), "") -> 3205.1833 | R4: =LEFT(A4,3) -> VLG | S4: =IF($D4="LEBL", IF(COUNTIF('Paises ECAC'!B:B, C4)>0, "ECAC","NO ECAC"), "") -> NO ECAC
A5: VLG2479 | B5: A321 | C5: GCRR | D5: LEBL | E5: ECMQL | F5: 360 | G5: 0.92986111 | H5: 10 | I5: 0.041666667 | J5: {=XLOOKUP(B5,cat!B:B,cat!C:C)} -> D | K5: {=XLOOKUP(B5,cat!B:B,cat!D:D)} -> 207 | L5: =mod(I5-G5,1) -> 0.11180556 | M5: =IF($D5="LEBL", IF($L5-(18.3/1440)-($H5/1440)<0, $L5-($H5/1440), $L5-(18.3/1440)-($H5/1440) ), "") -> 0.092152778 | N5: 830 | O5: D | Q5: =IFERROR(M5*24*XLOOKUP(J5,$O$2:$O$7,$N$2:$N$7), "") -> 1835.6833 | R5: =LEFT(A5,3) -> VLG | S5: =IF($D5="LEBL", IF(COUNTIF('Paises ECAC'!B:B, C5)>0, "ECAC","NO ECAC"), "") -> ECAC
A6: RYR56YL | B6: B38M | C6: EIDW | D6: LEBL | E6: EIIHE | F6: 370 | G6: 0.96180556 | H6: 15 | I6: 0.045138889 | J6: {=XLOOKUP(B6,cat!B:B,cat!C:C)} -> D | K6: {=XLOOKUP(B6,cat!B:B,cat!D:D)} -> 186 | L6: =mod(I6-G6,1) -> 0.083333333 | M6: =IF($D6="LEBL", IF($L6-(18.3/1440)-($H6/1440)<0, $L6-($H6/1440), $L6-(18.3/1440)-($H6/1440) ), "") -> 0.060208333 | N6: 450 | O6: E | Q6: =IFERROR(M6*24*XLOOKUP(J6,$O$2:$O$7,$N$2:$N$7), "") -> 1199.35 | R6: =LEFT(A6,3) -> RYR | S6: =IF($D6="LEBL", IF(COUNTIF('Paises ECAC'!B:B, C6)>0, "ECAC","NO ECAC"), "") -> ECAC
A7: ANE3053 | B7: CRJX | C7: LEGE | D7: LEBL | E7: ECMLN | F7: 180 | G7: 0.027083333 | H7: 9 | I7: 0.048611111 | J7: {=XLOOKUP(B7,cat!B:B,cat!C:C)} -> E | K7: {=XLOOKUP(B7,cat!B:B,cat!D:D)} -> 100 | L7: =mod(I7-G7,1) -> 0.021527778 | M7: =IF($D7="LEBL", IF($L7-(18.3/1440)-($H7/1440)<0, $L7-($H7/1440), $L7-(18.3/1440)-($H7/1440) ), "") -> 0.0025694444 | N7: 180 | O7: F | Q7: =IFERROR(M7*24*XLOOKUP(J7,$O$2:$O$7,$N$2:$N$7), "") -> 27.75 | R7: =LEFT(A7,3) -> ANE | S7: =IF($D7="LEBL", IF(COUNTIF('Paises ECAC'!B:B, C7)>0, "ECAC","NO ECAC"), "") -> ECAC
A8: VLG7887 | B8: A320 | C8: GOBD | D8: LEBL | E8: ECMAI | F8: 380 | G8: 0.86805556 | H8: 10 | I8: 0.048611111 | J8: {=XLOOKUP(B8,cat!B:B,cat!C:C)} -> D | K8: {=XLOOKUP(B8,cat!B:B,cat!D:D)} -> 173 | L8: =mod(I8-G8,1) -> 0.18055556 | M8: =IF($D8="LEBL", IF($L8-(18.3/1440)-($H8/1440)<0, $L8-($H8/1440), $L8-(18.3/1440)-($H8/1440) ), "") -> 0.16090278 | Q8: =IFERROR(M8*24*XLOOKUP(J8,$O$2:$O$7,$N$2:$N$7), "") -> 3205.1833 | R8: =LEFT(A8,3) -> VLG | S8: =IF($D8="LEBL", IF(COUNTIF('Paises ECAC'!B:B, C8)>0, "ECAC","NO ECAC"), "") -> NO ECAC
A9: TVP7318 | B9: B38M | C9: LKPR | D9: LEBL | E9: OKSWF | F9: 370 | G9: 0.98680556 | H9: 7 | I9: 0.069444444 | J9: {=XLOOKUP(B9,cat!B:B,cat!C:C)} -> D | K9: {=XLOOKUP(B9,cat!B:B,cat!D:D)} -> 186 | L9: =mod(I9-G9,1) -> 0.082638889 | M9: =IF($D9="LEBL", IF($L9-(18.3/1440)-($H9/1440)<0, $L9-($H9/1440), $L9-(18.3/1440)-($H9/1440) ), "") -> 0.065069444 | P9: Slots | Q9: =IFERROR(M9*24*XLOOKUP(J9,$O$2:$O$7,$N$2:$N$7), "") -> 1296.1833 | R9: =LEFT(A9,3) -> TVP | S9: =IF($D9="LEBL", IF(COUNTIF('Paises ECAC'!B:B, C9)>0, "ECAC","NO ECAC"), "") -> ECAC
A10: IBE2602 | B10: A332 | C10: SAEZ | D10: LEBL | E10: ECNEN | F10: 400 | G10: 0.625 | H10: 10 | I10: 0.12152778 | J10: {=XLOOKUP(B10,cat!B:B,cat!C:C)} -> B | K10: {=XLOOKUP(B10,cat!B:B,cat!D:D)} -> 281 | L10: =mod(I10-G10,1) -> 0.49652778 | M10: =IF($D10="LEBL", IF($L10-(18.3/1440)-($H10/1440)<0, $L10-($H10/1440), $L10-(18.3/1440)-($H10/1440) ), "") -> 0.476875 | N10: AAR | O10: 40 | P10: 1.5 min | Q10: =IFERROR(M10*24*XLOOKUP(J10,$O$2:$O$7,$N$2:$N$7), "") -> 10300.5 | R10: =LEFT(A10,3) -> IBE | S10: =IF($D10="LEBL", IF(COUNTIF('Paises ECAC'!B:B, C10)>0, "ECAC","NO ECAC"), "") -> NO ECAC
A11: VLG101P | B11: A20N | C11: LFML | D11: LEBL | E11: ECNDA | F11: 290 | G11: 0.10277778 | H11: 6 | I11: 0.125 | J11: {=XLOOKUP(B11,cat!B:B,cat!C:C)} -> D | K11: {=XLOOKUP(B11,cat!B:B,cat!D:D)} -> 180 | L11: =mod(I11-G11,1) -> 0.022222222 | M11: =IF($D11="LEBL", IF($L11-(18.3/1440)-($H11/1440)<0, $L11-($H11/1440), $L11-(18.3/1440)-($H11/1440) ), "") -> 0.0053472222 | N11: PAAR | O11: 20 | P11: 3 min | Q11: =IFERROR(M11*24*XLOOKUP(J11,$O$2:$O$7,$N$2:$N$7), "") -> 106.51667 | R11: =LEFT(A11,3) -> VLG | S11: =IF($D11="LEBL", IF(COUNTIF('Paises ECAC'!B:B, C11)>0, "ECAC","NO ECAC"), "") -> ECAC
A12: TVP7319 | B12: B38M | C12: LEBL | D12: EPWA | E12: OKSWF | F12: 360 | G12: 0.12291667 | H12: 20 | I12: 0.23611111 | J12: {=XLOOKUP(B12,cat!B:B,cat!C:C)} -> D | K12: {=XLOOKUP(B12,cat!B:B,cat!D:D)} -> 186 | L12: =mod(I12-G12,1) -> 0.11319444 | M12: =IF($D12="LEBL", IF($L12-(18.3/1440)-($H12/1440)<0, $L12-($H12/1440), $L12-(18.3/1440)-($H12/1440) ), "") | Q12: =IFERROR(M12*24*XLOOKUP(J12,$O$2:$O$7,$N$2:$N$7), "") -> 0 | R12: =LEFT(A12,3) -> TVP | S12: =IF($D12="LEBL", IF(COUNTIF('Paises ECAC'!B:B, C12)>0, "ECAC","NO ECAC"), "")
A13: VLG72JR | B13: A320 | C13: LEBL | D13: GMTT | E13: ECMBE | F13: 350 | G13: 0.12708333 | H13: 8 | I13: 0.1875 | J13: {=XLOOKUP(B13,cat!B:B,cat!C:C)} -> D | K13: {=XLOOKUP(B13,cat!B:B,cat!D:D)} -> 173 | L13: =mod(I13-G13,1) -> 0.060416667 | M13: =IF($D13="LEBL", IF($L13-(18.3/1440)-($H13/1440)<0, $L13-($H13/1440), $L13-(18.3/1440)-($H13/1440) ), "") | N13: Hfile | O13: 0.25 | Q13: =IFERROR(M13*24*XLOOKUP(J13,$O$2:$O$7,$N$2:$N$7), "") -> 0 | R13: =LEFT(A13,3) -> VLG | S13: =IF($D13="LEBL", IF(COUNTIF('Paises ECAC'!B:B, C13)>0, "ECAC","NO ECAC"), "")
A14: VLG303P | B14: A320 | C14: LEBL | D14: LFPO | E14: ECKLT | F14: 380 | G14: 0.12986111 | H14: 17 | I14: 0.18402778 | J14: {=XLOOKUP(B14,cat!B:B,cat!C:C)} -> D | K14: {=XLOOKUP(B14,cat!B:B,cat!D:D)} -> 173 | L14: =mod(I14-G14,1) -> 0.054166667 | M14: =IF($D14="LEBL", IF($L14-(18.3/1440)-($H14/1440)<0, $L14-($H14/1440), $L14-(18.3/1440)-($H14/1440) ), "") | N14: Hstart | O14: 0.33333333 | Q14: =IFERROR(M14*24*XLOOKUP(J14,$O$2:$O$7,$N$2:$N$7), "") -> 0 | R14: =LEFT(A14,3) -> VLG | S14: =IF($D14="LEBL", IF(COUNTIF('Paises ECAC'!B:B, C14)>0, "ECAC","NO ECAC"), "")
A15: IBE2606 | B15: A332 | C15: SCEL | D15: LEBL | E15: ECNNH | F15: 400 | G15: 0.60763889 | H15: 10 | I15: 0.14236111 | J15: {=XLOOKUP(B15,cat!B:B,cat!C:C)} -> B | K15: {=XLOOKUP(B15,cat!B:B,cat!D:D)} -> 281 | L15: =mod(I15-G15,1) -> 0.53472222 | M15: =IF($D15="LEBL", IF($L15-(18.3/1440)-($H15/1440)<0, $L15-($H15/1440), $L15-(18.3/1440)-($H15/1440) ), "") -> 0.51506944 | N15: Hend | O15: 0.58333333 | Q15: =IFERROR(M15*24*XLOOKUP(J15,$O$2:$O$7,$N$2:$N$7), "") -> 11125.5 | R15: =LEFT(A15,3) -> IBE | S15: =IF($D15="LEBL", IF(COUNTIF('Paises ECAC'!B:B, C15)>0, "ECAC","NO ECAC"), "") -> NO ECAC
A16: VLG2008 | B16: A320 | C16: LEBL | D16: LICB | E16: ECMBS | F16: 390 | G16: 0.15416667 | H16: 12 | I16: 0.21875 | J16: {=XLOOKUP(B16,cat!B:B,cat!C:C)} -> D | K16: {=XLOOKUP(B16,cat!B:B,cat!D:D)} -> 173 | L16: =mod(I16-G16,1) -> 0.064583333 | M16: =IF($D16="LEBL", IF($L16-(18.3/1440)-($H16/1440)<0, $L16-($H16/1440), $L16-(18.3/1440)-($H16/1440) ), "") | Q16: =IFERROR(M16*24*XLOOKUP(J16,$O$2:$O$7,$N$2:$N$7), "") -> 0 | R16: =LEFT(A16,3) -> VLG | S16: =IF($D16="LEBL", IF(COUNTIF('Paises ECAC'!B:B, C16)>0, "ECAC","NO ECAC"), "")
A17: VLG6DZ | B17: A320 | C17: LGIR | D17: LEBL | E17: ECKHN | F17: 360 | G17: 0.045138889 | H17: 10 | I17: 0.15625 | J17: {=XLOOKUP(B17,cat!B:B,cat!C:C)} -> D | K17: {=XLOOKUP(B17,cat!B:B,cat!D:D)} -> 173 | L17: =mod(I17-G17,1) -> 0.11111111 | M17: =IF($D17="LEBL", IF($L17-(18.3/1440)-($H17/1440)<0, $L17-($H17/1440), $L17-(18.3/1440)-($H17/1440) ), "") -> 0.091458333 | Q17: =IFERROR(M17*24*XLOOKUP(J17,$O$2:$O$7,$N$2:$N$7), "") -> 1821.85 | R17: =LEFT(A17,3) -> VLG | S17: =IF($D17="LEBL", IF(COUNTIF('Paises ECAC'!B:B, C17)>0, "ECAC","NO ECAC"), "") -> ECAC
A18: VLG9YD | B18: A20N | C18: LEBL | D18: EKCH | E18: ECNCS | F18: 390 | G18: 0.15763889 | H18: 12 | I18: 0.26736111 | J18: {=XLOOKUP(B18,cat!B:B,cat!C:C)} -> D | K18: {=XLOOKUP(B18,cat!B:B,cat!D:D)} -> 180 | L18: =mod(I18-G18,1) -> 0.10972222 | M18: =IF($D18="LEBL", IF($L18-(18.3/1440)-($H18/1440)<0, $L18-($H18/1440), $L18-(18.3/1440)-($H18/1440) ), "") | Q18: =IFERROR(M18*24*XLOOKUP(J18,$O$2:$O$7,$N$2:$N$7), "") -> 0 | R18: =LEFT(A18,3) -> VLG | S18: =IF($D18="LEBL", IF(COUNTIF('Paises ECAC'!B:B, C18)>0, "ECAC","NO ECAC"), "")
A19: VLG7480 | B19: A320 | C19: LEBL | D19: DAOO | E19: ECODN | F19: 310 | G19: 0.15347222 | H19: 11 | I19: 0.20138889 | J19: {=XLOOKUP(B19,cat!B:B,cat!C:C)} -> D | K19: {=XLOOKUP(B19,cat!B:B,cat!D:D)} -> 173 | L19: =mod(I19-G19,1) -> 0.047916667 | M19: =IF($D19="LEBL", IF($L19-(18.3/1440)-($H19/1440)<0, $L19-($H19/1440), $L19-(18.3/1440)-($H19/1440) ), "") | Q19: =IFERROR(M19*24*XLOOKUP(J19,$O$2:$O$7,$N$2:$N$7), "") -> 0 | R19: =LEFT(A19,3) -> VLG | S19: =IF($D19="LEBL", IF(COUNTIF('Paises ECAC'!B:B, C19)>0, "ECAC","NO ECAC"), "")
A20: RYR26UP | B20: B738 | C20: LEBL | D20: EGNX | E20: 9HQFK | F20: 380 | G20: 0.17013889 | H20: 20 | I20: 0.24305556 | J20: {=XLOOKUP(B20,cat!B:B,cat!C:C)} -> D | K20: {=XLOOKUP(B20,cat!B:B,cat!D:D)} -> 184 | L20: =mod(I20-G20,1) -> 0.072916667 | M20: =IF($D20="LEBL", IF($L20-(18.3/1440)-($H20/1440)<0, $L20-($H20/1440), $L20-(18.3/1440)-($H20/1440) ), "") | Q20: =IFERROR(M20*24*XLOOKUP(J20,$O$2:$O$7,$N$2:$N$7), "") -> 0 | R20: =LEFT(A20,3) -> RYR | S20: =IF($D20="LEBL", IF(COUNTIF('Paises ECAC'!B:B, C20)>0, "ECAC","NO ECAC"), "")
A21: VLG94PH | B21: A320 | C21: LEBL | D21: LIMC | E21: ECOJG | F21: 300 | G21: 0.16666667 | H21: 8 | I21: 0.21180556 | J21: {=XLOOKUP(B21,cat!B:B,cat!C:C)} -> D | K21: {=XLOOKUP(B21,cat!B:B,cat!D:D)} -> 173 | L21: =mod(I21-G21,1) -> 0.045138889 | M21: =IF($D21="LEBL", IF($L21-(18.3/1440)-($H21/1440)<0, $L21-($H21/1440), $L21-(18.3/1440)-($H21/1440) ), "") | Q21: =IFERROR(M21*24*XLOOKUP(J21,$O$2:$O$7,$N$2:$N$7), "") -> 0 | R21: =LEFT(A21,3) -> VLG | S21: =IF($D21="LEBL", IF(COUNTIF('Paises ECAC'!B:B, C21)>0, "ECAC","NO ECAC"), "")
A22: RYR38AV | B22: B738 | C22: LEBL | D22: LIPZ | E22: EIDLD | F22: 380 | G22: 0.17013889 | H22: 20 | I22: 0.22569444 | J22: {=XLOOKUP(B22,cat!B:B,cat!C:C)} -> D | K22: {=XLOOKUP(B22,cat!B:B,cat!D:D)} -> 184 | L22: =mod(I22-G22,1) -> 0.055555556 | M22: =IF($D22="LEBL", IF($L22-(18.3/1440)-($H22/1440)<0, $L22-($H22/1440), $L22-(18.3/1440)-($H22/1440) ), "") | Q22: =IFERROR(M22*24*XLOOKUP(J22,$O$2:$O$7,$N$2:$N$7), "") -> 0 | R22: =LEFT(A22,3) -> RYR | S22: =IF($D22="LEBL", IF(COUNTIF('Paises ECAC'!B:B, C22)>0, "ECAC","NO ECAC"), "")
A23: VLG8113 | B23: A320 | C23: LGAV | D23: LEBL | E23: ECOFX | F23: 360 | G23: 0.070138889 | H23: 13 | I23: 0.17013889 | J23: {=XLOOKUP(B23,cat!B:B,cat!C:C)} -> D | K23: {=XLOOKUP(B23,cat!B:B,cat!D:D)} -> 173 | L23: =mod(I23-G23,1) -> 0.1 | M23: =IF($D23="LEBL", IF($L23-(18.3/1440)-($H23/1440)<0, $L23-($H23/1440), $L23-(18.3/1440)-($H23/1440) ), "") -> 0.078263889 | Q23: =IFERROR(M23*24*XLOOKUP(J23,$O$2:$O$7,$N$2:$N$7), "") -> 1559.0167 | R23: =LEFT(A23,3) -> VLG | S23: =IF($D23="LEBL", IF(COUNTIF('Paises ECAC'!B:B, C23)>0, "ECAC","NO ECAC"), "") -> ECAC
A24: RYR73JP | B24: B38M | C24: LEBL | D24: LIMF | E24: EIIHE | F24: 300 | G24: 0.17222222 | H24: 0 | I24: 0.22222222 | J24: {=XLOOKUP(B24,cat!B:B,cat!C:C)} -> D | K24: {=XLOOKUP(B24,cat!B:B,cat!D:D)} -> 186 | L24: =mod(I24-G24,1) -> 0.05 | M24: =IF($D24="LEBL", IF($L24-(18.3/1440)-($H24/1440)<0, $L24-($H24/1440), $L24-(18.3/1440)-($H24/1440) ), "") | Q24: =IFERROR(M24*24*XLOOKUP(J24,$O$2:$O$7,$N$2:$N$7), "") -> 0 | R24: =LEFT(A24,3) -> RYR | S24: =IF($D24="LEBL", IF(COUNTIF('Paises ECAC'!B:B, C24)>0, "ECAC","NO ECAC"), "")
A25: TAP1041 | B25: A321 | C25: LEBL | D25: LPPT | E25: CSTJE | F25: 330 | G25: 0.17916667 | H25: 8 | I25: 0.23958333 | J25: {=XLOOKUP(B25,cat!B:B,cat!C:C)} -> D | K25: {=XLOOKUP(B25,cat!B:B,cat!D:D)} -> 207 | L25: =mod(I25-G25,1) -> 0.060416667 | M25: =IF($D25="LEBL", IF($L25-(18.3/1440)-($H25/1440)<0, $L25-($H25/1440), $L25-(18.3/1440)-($H25/1440) ), "") | Q25: =IFERROR(M25*24*XLOOKUP(J25,$O$2:$O$7,$N$2:$N$7), "") -> 0 | R25: =LEFT(A25,3) -> TAP | S25: =IF($D25="LEBL", IF(COUNTIF('Paises ECAC'!B:B, C25)>0, "ECAC","NO ECAC"), "")
A26: RYR4WX | B26: B738 | C26: LEBL | D26: LFOB | E26: EIEBF | F26: 340 | G26: 0.18472222 | H26: 20 | I26: 0.23958333 | J26: {=XLOOKUP(B26,cat!B:B,cat!C:C)} -> D | K26: {=XLOOKUP(B26,cat!B:B,cat!D:D)} -> 184 | L26: =mod(I26-G26,1) -> 0.054861111 | M26: =IF($D26="LEBL", IF($L26-(18.3/1440)-($H26/1440)<0, $L26-($H26/1440), $L26-(18.3/1440)-($H26/1440) ), "") | Q26: =IFERROR(M26*24*XLOOKUP(J26,$O$2:$O$7,$N$2:$N$7), "") -> 0 | R26: =LEFT(A26,3) -> RYR | S26: =IF($D26="LEBL", IF(COUNTIF('Paises ECAC'!B:B, C26)>0, "ECAC","NO ECAC"), "")
A27: VLG5VH | B27: A320 | C27: LEBL | D27: LMML | E27: ECKRH | F27: 370 | G27: 0.17152778 | H27: 17 | I27: 0.25347222 | J27: {=XLOOKUP(B27,cat!B:B,cat!C:C)} -> D | K27: {=XLOOKUP(B27,cat!B:B,cat!D:D)} -> 173 | L27: =mod(I27-G27,1) -> 0.081944444 | M27: =IF($D27="LEBL", IF($L27-(18.3/1440)-($H27/1440)<0, $L27-($H27/1440), $L27-(18.3/1440)-($H27/1440) ), "") | Q27: =IFERROR(M27*24*XLOOKUP(J27,$O$2:$O$7,$N$2:$N$7), "") -> 0 | R27: =LEFT(A27,3) -> VLG | S27: =IF($D27="LEBL", IF(COUNTIF('Paises ECAC'!B:B, C27)>0, "ECAC","NO ECAC"), "")
... A1102: IBE2601 | B1102: A332 | C1102: LEBL | D1102: SAEZ | E1102: ECNRH | F1102: 400 | G1102: 0.9875 | H1102: 12 | I1102: 0.5 | J1102: {=XLOOKUP(B1102,cat!B:B,cat!C:C)} -> B | K1102: {=XLOOKUP(B1102,cat!B:B,cat!D:D)} -> 281 | L1102: =mod(I1102-G1102,1) -> 0.5125 | M1102: =IF($D1102="LEBL", IF($L1102-(18.3/1440)-($H1102/1440)<0, $L1102-($H1102/1440), $L1102-(18.3/1440)-($H1102/1440) ), "") | Q1102: =IFERROR(M1102*24*XLOOKUP(J1102,$O$2:$O$7,$N$2:$N$7), "") -> 0 | R1102: =LEFT(A1102,3) -> IBE | S1102: =IF($D1102="LEBL", IF(COUNTIF('Paises ECAC'!B:B, C1102)>0, "ECAC","NO ECAC"), "")

Sheet LLEGADAS
A1: ARCID | B1: ATYP | C1: ADEP | D1: ADES | E1: RM | F1: ARF | G1: ETD | H1: TT | I1: ETA | J1: Aircraft category | K1: Seats | L1: Flight_time(ETA-ETD) | M1: Arrivalf_time | O1: Flight_Distance (km) | P1: Flight Airline | Q1: ECAC
A2: =IFERROR(__xludf.DUMMYFUNCTION("FILTER(LEBL_10AUG2025!A:M, LEBL_10AUG2025!D:D = ""LEBL"")"),"RYR404A") -> RYR404A | B2: =IFERROR(__xludf.DUMMYFUNCTION("""COMPUTED_VALUE"""),"B738") -> B738 | C2: =IFERROR(__xludf.DUMMYFUNCTION("""COMPUTED_VALUE"""),"LPPR") -> LPPR | D2: =IFERROR(__xludf.DUMMYFUNCTION("""COMPUTED_VALUE"""),"LEBL") -> LEBL | E2: =IFERROR(__xludf.DUMMYFUNCTION("""COMPUTED_VALUE"""),"EIDCJ") -> EIDCJ | F2: =IFERROR(__xludf.DUMMYFUNCTION("""COMPUTED_VALUE"""),380.0) -> 380 | G2: =IFERROR(__xludf.DUMMYFUNCTION("""COMPUTED_VALUE"""),0.9513888888888888) -> 0.95138889 | H2: =IFERROR(__xludf.DUMMYFUNCTION("""COMPUTED_VALUE"""),15.0) -> 15 | I2: =IFERROR(__xludf.DUMMYFUNCTION("""COMPUTED_VALUE"""),0.003472222222222222) -> 0.0034722222 | J2: =IFERROR(__xludf.DUMMYFUNCTION("""COMPUTED_VALUE"""),"D") -> D | K2: =IFERROR(__xludf.DUMMYFUNCTION("""COMPUTED_VALUE"""),184.0) -> 184 | L2: =IFERROR(__xludf.DUMMYFUNCTION("""COMPUTED_VALUE"""),0.05208333333333337) -> 0.052083333 | M2: =IFERROR(__xludf.DUMMYFUNCTION("""COMPUTED_VALUE"""),0.02895833333333337) -> 0.028958333 | O2: =IFERROR(__xludf.DUMMYFUNCTION("FILTER(LEBL_10AUG2025!Q:S, LEBL_10AUG2025!D:D = ""LEBL"")"),576.8500000000008) -> 576.85 | P2: =IFERROR(__xludf.DUMMYFUNCTION("""COMPUTED_VALUE"""),"RYR") -> RYR | Q2: =IFERROR(__xludf.DUMMYFUNCTION("""COMPUTED_VALUE"""),"ECAC") -> ECAC
A3: =IFERROR(__xludf.DUMMYFUNCTION("""COMPUTED_VALUE"""),"VLG7575") -> VLG7575 | B3: =IFERROR(__xludf.DUMMYFUNCTION("""COMPUTED_VALUE"""),"A320") -> A320 | C3: =IFERROR(__xludf.DUMMYFUNCTION("""COMPUTED_VALUE"""),"GBYD") -> GBYD | D3: =IFERROR(__xludf.DUMMYFUNCTION("""COMPUTED_VALUE"""),"LEBL") -> LEBL | E3: =IFERROR(__xludf.DUMMYFUNCTION("""COMPUTED_VALUE"""),"ECLVV") -> ECLVV | F3: =IFERROR(__xludf.DUMMYFUNCTION("""COMPUTED_VALUE"""),380.0) -> 380 | G3: =IFERROR(__xludf.DUMMYFUNCTION("""COMPUTED_VALUE"""),0.8506944444444444) -> 0.85069444 | H3: =IFERROR(__xludf.DUMMYFUNCTION("""COMPUTED_VALUE"""),10.0) -> 10 | I3: =IFERROR(__xludf.DUMMYFUNCTION("""COMPUTED_VALUE"""),0.03125) -> 0.03125 | J3: =IFERROR(__xludf.DUMMYFUNCTION("""COMPUTED_VALUE"""),"D") -> D | K3: =IFERROR(__xludf.DUMMYFUNCTION("""COMPUTED_VALUE"""),173.0) -> 173 | L3: =IFERROR(__xludf.DUMMYFUNCTION("""COMPUTED_VALUE"""),0.18055555555555558) -> 0.18055556 | M3: =IFERROR(__xludf.DUMMYFUNCTION("""COMPUTED_VALUE"""),0.1609027777777778) -> 0.16090278 | O3: =IFERROR(__xludf.DUMMYFUNCTION("""COMPUTED_VALUE"""),3205.183333333334) -> 3205.1833 | P3: =IFERROR(__xludf.DUMMYFUNCTION("""COMPUTED_VALUE"""),"VLG") -> VLG | Q3: =IFERROR(__xludf.DUMMYFUNCTION("""COMPUTED_VALUE"""),"NO ECAC") -> NO ECAC
A4: =IFERROR(__xludf.DUMMYFUNCTION("""COMPUTED_VALUE"""),"VLG2479") -> VLG2479 | B4: =IFERROR(__xludf.DUMMYFUNCTION("""COMPUTED_VALUE"""),"A321") -> A321 | C4: =IFERROR(__xludf.DUMMYFUNCTION("""COMPUTED_VALUE"""),"GCRR") -> GCRR | D4: =IFERROR(__xludf.DUMMYFUNCTION("""COMPUTED_VALUE"""),"LEBL") -> LEBL | E4: =IFERROR(__xludf.DUMMYFUNCTION("""COMPUTED_VALUE"""),"ECMQL") -> ECMQL | F4: =IFERROR(__xludf.DUMMYFUNCTION("""COMPUTED_VALUE"""),360.0) -> 360 | G4: =IFERROR(__xludf.DUMMYFUNCTION("""COMPUTED_VALUE"""),0.9298611111111111) -> 0.92986111 | H4: =IFERROR(__xludf.DUMMYFUNCTION("""COMPUTED_VALUE"""),10.0) -> 10 | I4: =IFERROR(__xludf.DUMMYFUNCTION("""COMPUTED_VALUE"""),0.041666666666666664) -> 0.041666667 | J4: =IFERROR(__xludf.DUMMYFUNCTION("""COMPUTED_VALUE"""),"D") -> D | K4: =IFERROR(__xludf.DUMMYFUNCTION("""COMPUTED_VALUE"""),207.0) -> 207 | L4: =IFERROR(__xludf.DUMMYFUNCTION("""COMPUTED_VALUE"""),0.11180555555555549) -> 0.11180556 | M4: =IFERROR(__xludf.DUMMYFUNCTION("""COMPUTED_VALUE"""),0.09215277777777771) -> 0.092152778 | O4: =IFERROR(__xludf.DUMMYFUNCTION("""COMPUTED_VALUE"""),1835.683333333332) -> 1835.6833 | P4: =IFERROR(__xludf.DUMMYFUNCTION("""COMPUTED_VALUE"""),"VLG") -> VLG | Q4: =IFERROR(__xludf.DUMMYFUNCTION("""COMPUTED_VALUE"""),"ECAC") -> ECAC
A5: =IFERROR(__xludf.DUMMYFUNCTION("""COMPUTED_VALUE"""),"RYR56YL") -> RYR56YL | B5: =IFERROR(__xludf.DUMMYFUNCTION("""COMPUTED_VALUE"""),"B38M") -> B38M | C5: =IFERROR(__xludf.DUMMYFUNCTION("""COMPUTED_VALUE"""),"EIDW") -> EIDW | D5: =IFERROR(__xludf.DUMMYFUNCTION("""COMPUTED_VALUE"""),"LEBL") -> LEBL | E5: =IFERROR(__xludf.DUMMYFUNCTION("""COMPUTED_VALUE"""),"EIIHE") -> EIIHE | F5: =IFERROR(__xludf.DUMMYFUNCTION("""COMPUTED_VALUE"""),370.0) -> 370 | G5: =IFERROR(__xludf.DUMMYFUNCTION("""COMPUTED_VALUE"""),0.9618055555555556) -> 0.96180556 | H5: =IFERROR(__xludf.DUMMYFUNCTION("""COMPUTED_VALUE"""),15.0) -> 15 | I5: =IFERROR(__xludf.DUMMYFUNCTION("""COMPUTED_VALUE"""),0.04513888888888889) -> 0.045138889 | J5: =IFERROR(__xludf.DUMMYFUNCTION("""COMPUTED_VALUE"""),"D") -> D | K5: =IFERROR(__xludf.DUMMYFUNCTION("""COMPUTED_VALUE"""),186.0) -> 186 | L5: =IFERROR(__xludf.DUMMYFUNCTION("""COMPUTED_VALUE"""),0.08333333333333326) -> 0.083333333 | M5: =IFERROR(__xludf.DUMMYFUNCTION("""COMPUTED_VALUE"""),0.06020833333333326) -> 0.060208333 | O5: =IFERROR(__xludf.DUMMYFUNCTION("""COMPUTED_VALUE"""),1199.3499999999985) -> 1199.35 | P5: =IFERROR(__xludf.DUMMYFUNCTION("""COMPUTED_VALUE"""),"RYR") -> RYR | Q5: =IFERROR(__xludf.DUMMYFUNCTION("""COMPUTED_VALUE"""),"ECAC") -> ECAC
A6: =IFERROR(__xludf.DUMMYFUNCTION("""COMPUTED_VALUE"""),"ANE3053") -> ANE3053 | B6: =IFERROR(__xludf.DUMMYFUNCTION("""COMPUTED_VALUE"""),"CRJX") -> CRJX | C6: =IFERROR(__xludf.DUMMYFUNCTION("""COMPUTED_VALUE"""),"LEGE") -> LEGE | D6: =IFERROR(__xludf.DUMMYFUNCTION("""COMPUTED_VALUE"""),"LEBL") -> LEBL | E6: =IFERROR(__xludf.DUMMYFUNCTION("""COMPUTED_VALUE"""),"ECMLN") -> ECMLN | F6: =IFERROR(__xludf.DUMMYFUNCTION("""COMPUTED_VALUE"""),180.0) -> 180 | G6: =IFERROR(__xludf.DUMMYFUNCTION("""COMPUTED_VALUE"""),0.027083333333333334) -> 0.027083333 | H6: =IFERROR(__xludf.DUMMYFUNCTION("""COMPUTED_VALUE"""),9.0) -> 9 | I6: =IFERROR(__xludf.DUMMYFUNCTION("""COMPUTED_VALUE"""),0.04861111111111111) -> 0.048611111 | J6: =IFERROR(__xludf.DUMMYFUNCTION("""COMPUTED_VALUE"""),"E") -> E | K6: =IFERROR(__xludf.DUMMYFUNCTION("""COMPUTED_VALUE"""),100.0) -> 100 | L6: =IFERROR(__xludf.DUMMYFUNCTION("""COMPUTED_VALUE"""),0.021527777777777778) -> 0.021527778 | M6: =IFERROR(__xludf.DUMMYFUNCTION("""COMPUTED_VALUE"""),0.0025694444444444436) -> 0.0025694444 | O6: =IFERROR(__xludf.DUMMYFUNCTION("""COMPUTED_VALUE"""),27.749999999999993) -> 27.75 | P6: =IFERROR(__xludf.DUMMYFUNCTION("""COMPUTED_VALUE"""),"ANE") -> ANE | Q6: =IFERROR(__xludf.DUMMYFUNCTION("""COMPUTED_VALUE"""),"ECAC") -> ECAC
A7: =IFERROR(__xludf.DUMMYFUNCTION("""COMPUTED_VALUE"""),"VLG7887") -> VLG7887 | B7: =IFERROR(__xludf.DUMMYFUNCTION("""COMPUTED_VALUE"""),"A320") -> A320 | C7: =IFERROR(__xludf.DUMMYFUNCTION("""COMPUTED_VALUE"""),"GOBD") -> GOBD | D7: =IFERROR(__xludf.DUMMYFUNCTION("""COMPUTED_VALUE"""),"LEBL") -> LEBL | E7: =IFERROR(__xludf.DUMMYFUNCTION("""COMPUTED_VALUE"""),"ECMAI") -> ECMAI | F7: =IFERROR(__xludf.DUMMYFUNCTION("""COMPUTED_VALUE"""),380.0) -> 380 | G7: =IFERROR(__xludf.DUMMYFUNCTION("""COMPUTED_VALUE"""),0.8680555555555556) -> 0.86805556 | H7: =IFERROR(__xludf.DUMMYFUNCTION("""COMPUTED_VALUE"""),10.0) -> 10 | I7: =IFERROR(__xludf.DUMMYFUNCTION("""COMPUTED_VALUE"""),0.04861111111111111) -> 0.048611111 | J7: =IFERROR(__xludf.DUMMYFUNCTION("""COMPUTED_VALUE"""),"D") -> D | K7: =IFERROR(__xludf.DUMMYFUNCTION("""COMPUTED_VALUE"""),173.0) -> 173 | L7: =IFERROR(__xludf.DUMMYFUNCTION("""COMPUTED_VALUE"""),0.18055555555555558) -> 0.18055556 | M7: =IFERROR(__xludf.DUMMYFUNCTION("""COMPUTED_VALUE"""),0.1609027777777778) -> 0.16090278 | O7: =IFERROR(__xludf.DUMMYFUNCTION("""COMPUTED_VALUE"""),3205.183333333334) -> 3205.1833 | P7: =IFERROR(__xludf.DUMMYFUNCTION("""COMPUTED_VALUE"""),"VLG") -> VLG | Q7: =IFERROR(__xludf.DUMMYFUNCTION("""COMPUTED_VALUE"""),"NO ECAC") -> NO ECAC
A8: =IFERROR(__xludf.DUMMYFUNCTION("""COMPUTED_VALUE"""),"TVP7318") -> TVP7318 | B8: =IFERROR(__xludf.DUMMYFUNCTION("""COMPUTED_VALUE"""),"B38M") -> B38M | C8: =IFERROR(__xludf.DUMMYFUNCTION("""COMPUTED_VALUE"""),"LKPR") -> LKPR | D8: =IFERROR(__xludf.DUMMYFUNCTION("""COMPUTED_VALUE"""),"LEBL") -> LEBL | E8: =IFERROR(__xludf.DUMMYFUNCTION("""COMPUTED_VALUE"""),"OKSWF") -> OKSWF | F8: =IFERROR(__xludf.DUMMYFUNCTION("""COMPUTED_VALUE"""),370.0) -> 370 | G8: =IFERROR(__xludf.DUMMYFUNCTION("""COMPUTED_VALUE"""),0.9868055555555556) -> 0.98680556 | H8: =IFERROR(__xludf.DUMMYFUNCTION("""COMPUTED_VALUE"""),7.0) -> 7 | I8: =IFERROR(__xludf.DUMMYFUNCTION("""COMPUTED_VALUE"""),0.06944444444444445) -> 0.069444444 | J8: =IFERROR(__xludf.DUMMYFUNCTION("""COMPUTED_VALUE"""),"D") -> D | K8: =IFERROR(__xludf.DUMMYFUNCTION("""COMPUTED_VALUE"""),186.0) -> 186 | L8: =IFERROR(__xludf.DUMMYFUNCTION("""COMPUTED_VALUE"""),0.08263888888888882) -> 0.082638889 | M8: =IFERROR(__xludf.DUMMYFUNCTION("""COMPUTED_VALUE"""),0.06506944444444437) -> 0.065069444 | O8: =IFERROR(__xludf.DUMMYFUNCTION("""COMPUTED_VALUE"""),1296.183333333332) -> 1296.1833 | P8: =IFERROR(__xludf.DUMMYFUNCTION("""COMPUTED_VALUE"""),"TVP") -> TVP | Q8: =IFERROR(__xludf.DUMMYFUNCTION("""COMPUTED_VALUE"""),"ECAC") -> ECAC
A9: =IFERROR(__xludf.DUMMYFUNCTION("""COMPUTED_VALUE"""),"IBE2602") -> IBE2602 | B9: =IFERROR(__xludf.DUMMYFUNCTION("""COMPUTED_VALUE"""),"A332") -> A332 | C9: =IFERROR(__xludf.DUMMYFUNCTION("""COMPUTED_VALUE"""),"SAEZ") -> SAEZ | D9: =IFERROR(__xludf.DUMMYFUNCTION("""COMPUTED_VALUE"""),"LEBL") -> LEBL | E9: =IFERROR(__xludf.DUMMYFUNCTION("""COMPUTED_VALUE"""),"ECNEN") -> ECNEN | F9: =IFERROR(__xludf.DUMMYFUNCTION("""COMPUTED_VALUE"""),400.0) -> 400 | G9: =IFERROR(__xludf.DUMMYFUNCTION("""COMPUTED_VALUE"""),0.625) -> 0.625 | H9: =IFERROR(__xludf.DUMMYFUNCTION("""COMPUTED_VALUE"""),10.0) -> 10 | I9: =IFERROR(__xludf.DUMMYFUNCTION("""COMPUTED_VALUE"""),0.12152777777777778) -> 0.12152778 | J9: =IFERROR(__xludf.DUMMYFUNCTION("""COMPUTED_VALUE"""),"B") -> B | K9: =IFERROR(__xludf.DUMMYFUNCTION("""COMPUTED_VALUE"""),281.0) -> 281 | L9: =IFERROR(__xludf.DUMMYFUNCTION("""COMPUTED_VALUE"""),0.4965277777777778) -> 0.49652778 | M9: =IFERROR(__xludf.DUMMYFUNCTION("""COMPUTED_VALUE"""),0.47687500000000005) -> 0.476875 | O9: =IFERROR(__xludf.DUMMYFUNCTION("""COMPUTED_VALUE"""),10300.5) -> 10300.5 | P9: =IFERROR(__xludf.DUMMYFUNCTION("""COMPUTED_VALUE"""),"IBE") -> IBE | Q9: =IFERROR(__xludf.DUMMYFUNCTION("""COMPUTED_VALUE"""),"NO ECAC") -> NO ECAC
A10: =IFERROR(__xludf.DUMMYFUNCTION("""COMPUTED_VALUE"""),"VLG101P") -> VLG101P | B10: =IFERROR(__xludf.DUMMYFUNCTION("""COMPUTED_VALUE"""),"A20N") -> A20N | C10: =IFERROR(__xludf.DUMMYFUNCTION("""COMPUTED_VALUE"""),"LFML") -> LFML | D10: =IFERROR(__xludf.DUMMYFUNCTION("""COMPUTED_VALUE"""),"LEBL") -> LEBL | E10: =IFERROR(__xludf.DUMMYFUNCTION("""COMPUTED_VALUE"""),"ECNDA") -> ECNDA | F10: =IFERROR(__xludf.DUMMYFUNCTION("""COMPUTED_VALUE"""),290.0) -> 290 | G10: =IFERROR(__xludf.DUMMYFUNCTION("""COMPUTED_VALUE"""),0.10277777777777777) -> 0.10277778 | H10: =IFERROR(__xludf.DUMMYFUNCTION("""COMPUTED_VALUE"""),6.0) -> 6 | I10: =IFERROR(__xludf.DUMMYFUNCTION("""COMPUTED_VALUE"""),0.125) -> 0.125 | J10: =IFERROR(__xludf.DUMMYFUNCTION("""COMPUTED_VALUE"""),"D") -> D | K10: =IFERROR(__xludf.DUMMYFUNCTION("""COMPUTED_VALUE"""),180.0) -> 180 | L10: =IFERROR(__xludf.DUMMYFUNCTION("""COMPUTED_VALUE"""),0.022222222222222227) -> 0.022222222 | M10: =IFERROR(__xludf.DUMMYFUNCTION("""COMPUTED_VALUE"""),0.005347222222222226) -> 0.0053472222 | O10: =IFERROR(__xludf.DUMMYFUNCTION("""COMPUTED_VALUE"""),106.51666666666675) -> 106.51667 | P10: =IFERROR(__xludf.DUMMYFUNCTION("""COMPUTED_VALUE"""),"VLG") -> VLG | Q10: =IFERROR(__xludf.DUMMYFUNCTION("""COMPUTED_VALUE"""),"ECAC") -> ECAC
A11: =IFERROR(__xludf.DUMMYFUNCTION("""COMPUTED_VALUE"""),"IBE2606") -> IBE2606 | B11: =IFERROR(__xludf.DUMMYFUNCTION("""COMPUTED_VALUE"""),"A332") -> A332 | C11: =IFERROR(__xludf.DUMMYFUNCTION("""COMPUTED_VALUE"""),"SCEL") -> SCEL | D11: =IFERROR(__xludf.DUMMYFUNCTION("""COMPUTED_VALUE"""),"LEBL") -> LEBL | E11: =IFERROR(__xludf.DUMMYFUNCTION("""COMPUTED_VALUE"""),"ECNNH") -> ECNNH | F11: =IFERROR(__xludf.DUMMYFUNCTION("""COMPUTED_VALUE"""),400.0) -> 400 | G11: =IFERROR(__xludf.DUMMYFUNCTION("""COMPUTED_VALUE"""),0.6076388888888888) -> 0.60763889 | H11: =IFERROR(__xludf.DUMMYFUNCTION("""COMPUTED_VALUE"""),10.0) -> 10 | I11: =IFERROR(__xludf.DUMMYFUNCTION("""COMPUTED_VALUE"""),0.1423611111111111) -> 0.14236111 | J11: =IFERROR(__xludf.DUMMYFUNCTION("""COMPUTED_VALUE"""),"B") -> B | K11: =IFERROR(__xludf.DUMMYFUNCTION("""COMPUTED_VALUE"""),281.0) -> 281 | L11: =IFERROR(__xludf.DUMMYFUNCTION("""COMPUTED_VALUE"""),0.5347222222222223) -> 0.53472222 | M11: =IFERROR(__xludf.DUMMYFUNCTION("""COMPUTED_VALUE"""),0.5150694444444446) -> 0.51506944 | O11: =IFERROR(__xludf.DUMMYFUNCTION("""COMPUTED_VALUE"""),11125.500000000004) -> 11125.5 | P11: =IFERROR(__xludf.DUMMYFUNCTION("""COMPUTED_VALUE"""),"IBE") -> IBE | Q11: =IFERROR(__xludf.DUMMYFUNCTION("""COMPUTED_VALUE"""),"NO ECAC") -> NO ECAC
A12: =IFERROR(__xludf.DUMMYFUNCTION("""COMPUTED_VALUE"""),"VLG6DZ") -> VLG6DZ | B12: =IFERROR(__xludf.DUMMYFUNCTION("""COMPUTED_VALUE"""),"A320") -> A320 | C12: =IFERROR(__xludf.DUMMYFUNCTION("""COMPUTED_VALUE"""),"LGIR") -> LGIR | D12: =IFERROR(__xludf.DUMMYFUNCTION("""COMPUTED_VALUE"""),"LEBL") -> LEBL | E12: =IFERROR(__xludf.DUMMYFUNCTION("""COMPUTED_VALUE"""),"ECKHN") -> ECKHN | F12: =IFERROR(__xludf.DUMMYFUNCTION("""COMPUTED_VALUE"""),360.0) -> 360 | G12: =IFERROR(__xludf.DUMMYFUNCTION("""COMPUTED_VALUE"""),0.04513888888888889) -> 0.045138889 | H12: =IFERROR(__xludf.DUMMYFUNCTION("""COMPUTED_VALUE"""),10.0) -> 10 | I12: =IFERROR(__xludf.DUMMYFUNCTION("""COMPUTED_VALUE"""),0.15625) -> 0.15625 | J12: =IFERROR(__xludf.DUMMYFUNCTION("""COMPUTED_VALUE"""),"D") -> D | K12: =IFERROR(__xludf.DUMMYFUNCTION("""COMPUTED_VALUE"""),173.0) -> 173 | L12: =IFERROR(__xludf.DUMMYFUNCTION("""COMPUTED_VALUE"""),0.1111111111111111) -> 0.11111111 | M12: =IFERROR(__xludf.DUMMYFUNCTION("""COMPUTED_VALUE"""),0.09145833333333332) -> 0.091458333 | O12: =IFERROR(__xludf.DUMMYFUNCTION("""COMPUTED_VALUE"""),1821.85) -> 1821.85 | P12: =IFERROR(__xludf.DUMMYFUNCTION("""COMPUTED_VALUE"""),"VLG") -> VLG | Q12: =IFERROR(__xludf.DUMMYFUNCTION("""COMPUTED_VALUE"""),"ECAC") -> ECAC
A13: =IFERROR(__xludf.DUMMYFUNCTION("""COMPUTED_VALUE"""),"VLG8113") -> VLG8113 | B13: =IFERROR(__xludf.DUMMYFUNCTION("""COMPUTED_VALUE"""),"A320") -> A320 | C13: =IFERROR(__xludf.DUMMYFUNCTION("""COMPUTED_VALUE"""),"LGAV") -> LGAV | D13: =IFERROR(__xludf.DUMMYFUNCTION("""COMPUTED_VALUE"""),"LEBL") -> LEBL | E13: =IFERROR(__xludf.DUMMYFUNCTION("""COMPUTED_VALUE"""),"ECOFX") -> ECOFX | F13: =IFERROR(__xludf.DUMMYFUNCTION("""COMPUTED_VALUE"""),360.0) -> 360 | G13: =IFERROR(__xludf.DUMMYFUNCTION("""COMPUTED_VALUE"""),0.07013888888888889) -> 0.070138889 | H13: =IFERROR(__xludf.DUMMYFUNCTION("""COMPUTED_VALUE"""),13.0) -> 13 | I13: =IFERROR(__xludf.DUMMYFUNCTION("""COMPUTED_VALUE"""),0.1701388888888889) -> 0.17013889 | J13: =IFERROR(__xludf.DUMMYFUNCTION("""COMPUTED_VALUE"""),"D") -> D | K13: =IFERROR(__xludf.DUMMYFUNCTION("""COMPUTED_VALUE"""),173.0) -> 173 | L13: =IFERROR(__xludf.DUMMYFUNCTION("""COMPUTED_VALUE"""),0.1) -> 0.1 | M13: =IFERROR(__xludf.DUMMYFUNCTION("""COMPUTED_VALUE"""),0.0782638888888889) -> 0.078263889 | O13: =IFERROR(__xludf.DUMMYFUNCTION("""COMPUTED_VALUE"""),1559.0166666666667) -> 1559.0167 | P13: =IFERROR(__xludf.DUMMYFUNCTION("""COMPUTED_VALUE"""),"VLG") -> VLG | Q13: =IFERROR(__xludf.DUMMYFUNCTION("""COMPUTED_VALUE"""),"ECAC") -> ECAC
A14: =IFERROR(__xludf.DUMMYFUNCTION("""COMPUTED_VALUE"""),"SIA388") -> SIA388 | B14: =IFERROR(__xludf.DUMMYFUNCTION("""COMPUTED_VALUE"""),"A359") -> A359 | C14: =IFERROR(__xludf.DUMMYFUNCTION("""COMPUTED_VALUE"""),"WSSS") -> WSSS | D14: =IFERROR(__xludf.DUMMYFUNCTION("""COMPUTED_VALUE"""),"LEBL") -> LEBL | E14: =IFERROR(__xludf.DUMMYFUNCTION("""COMPUTED_VALUE"""),"9VSMK") -> 9VSMK | F14: =IFERROR(__xludf.DUMMYFUNCTION("""COMPUTED_VALUE"""),400.0) -> 400 | G14: =IFERROR(__xludf.DUMMYFUNCTION("""COMPUTED_VALUE"""),0.65625) -> 0.65625 | H14: =IFERROR(__xludf.DUMMYFUNCTION("""COMPUTED_VALUE"""),10.0) -> 10 | I14: =IFERROR(__xludf.DUMMYFUNCTION("""COMPUTED_VALUE"""),0.18055555555555555) -> 0.18055556 | J14: =IFERROR(__xludf.DUMMYFUNCTION("""COMPUTED_VALUE"""),"B") -> B | K14: =IFERROR(__xludf.DUMMYFUNCTION("""COMPUTED_VALUE"""),297.0) -> 297 | L14: =IFERROR(__xludf.DUMMYFUNCTION("""COMPUTED_VALUE"""),0.5243055555555556) -> 0.52430556 | M14: =IFERROR(__xludf.DUMMYFUNCTION("""COMPUTED_VALUE"""),0.5046527777777778) -> 0.50465278 | O14: =IFERROR(__xludf.DUMMYFUNCTION("""COMPUTED_VALUE"""),10900.500000000002) -> 10900.5 | P14: =IFERROR(__xludf.DUMMYFUNCTION("""COMPUTED_VALUE"""),"SIA") -> SIA | Q14: =IFERROR(__xludf.DUMMYFUNCTION("""COMPUTED_VALUE"""),"NO ECAC") -> NO ECAC
A15: =IFERROR(__xludf.DUMMYFUNCTION("""COMPUTED_VALUE"""),"AAL66") -> AAL66 | B15: =IFERROR(__xludf.DUMMYFUNCTION("""COMPUTED_VALUE"""),"B772") -> B772 | C15: =IFERROR(__xludf.DUMMYFUNCTION("""COMPUTED_VALUE"""),"KJFK") -> KJFK | D15: =IFERROR(__xludf.DUMMYFUNCTION("""COMPUTED_VALUE"""),"LEBL") -> LEBL | E15: =IFERROR(__xludf.DUMMYFUNCTION("""COMPUTED_VALUE"""),"N795AN") -> N795AN | F15: =IFERROR(__xludf.DUMMYFUNCTION("""COMPUTED_VALUE"""),390.0) -> 390 | G15: =IFERROR(__xludf.DUMMYFUNCTION("""COMPUTED_VALUE"""),0.9069444444444444) -> 0.90694444 | H15: =IFERROR(__xludf.DUMMYFUNCTION("""COMPUTED_VALUE"""),36.0) -> 36 | I15: =IFERROR(__xludf.DUMMYFUNCTION("""COMPUTED_VALUE"""),0.1840277777777778) -> 0.18402778 | J15: =IFERROR(__xludf.DUMMYFUNCTION("""COMPUTED_VALUE"""),"B") -> B | K15: =IFERROR(__xludf.DUMMYFUNCTION("""COMPUTED_VALUE"""),296.0) -> 296 | L15: =IFERROR(__xludf.DUMMYFUNCTION("""COMPUTED_VALUE"""),0.27708333333333335) -> 0.27708333 | M15: =IFERROR(__xludf.DUMMYFUNCTION("""COMPUTED_VALUE"""),0.23937500000000003) -> 0.239375 | O15: =IFERROR(__xludf.DUMMYFUNCTION("""COMPUTED_VALUE"""),5170.500000000001) -> 5170.5 | P15: =IFERROR(__xludf.DUMMYFUNCTION("""COMPUTED_VALUE"""),"AAL") -> AAL | Q15: =IFERROR(__xludf.DUMMYFUNCTION("""COMPUTED_VALUE"""),"NO ECAC") -> NO ECAC
A16: =IFERROR(__xludf.DUMMYFUNCTION("""COMPUTED_VALUE"""),"ETD1HA") -> ETD1HA | B16: =IFERROR(__xludf.DUMMYFUNCTION("""COMPUTED_VALUE"""),"B78X") -> B78X | C16: =IFERROR(__xludf.DUMMYFUNCTION("""COMPUTED_VALUE"""),"OMAA") -> OMAA | D16: =IFERROR(__xludf.DUMMYFUNCTION("""COMPUTED_VALUE"""),"LEBL") -> LEBL | E16: =IFERROR(__xludf.DUMMYFUNCTION("""COMPUTED_VALUE"""),"A6BMI") -> A6BMI | F16: =IFERROR(__xludf.DUMMYFUNCTION("""COMPUTED_VALUE"""),380.0) -> 380 | G16: =IFERROR(__xludf.DUMMYFUNCTION("""COMPUTED_VALUE"""),0.9340277777777778) -> 0.93402778 | H16: =IFERROR(__xludf.DUMMYFUNCTION("""COMPUTED_VALUE"""),10.0) -> 10 | I16: =IFERROR(__xludf.DUMMYFUNCTION("""COMPUTED_VALUE"""),0.2013888888888889) -> 0.20138889 | J16: =IFERROR(__xludf.DUMMYFUNCTION("""COMPUTED_VALUE"""),"B") -> B | K16: =IFERROR(__xludf.DUMMYFUNCTION("""COMPUTED_VALUE"""),327.0) -> 327 | L16: =IFERROR(__xludf.DUMMYFUNCTION("""COMPUTED_VALUE"""),0.26736111111111116) -> 0.26736111 | M16: =IFERROR(__xludf.DUMMYFUNCTION("""COMPUTED_VALUE"""),0.2477083333333334) -> 0.24770833 | O16: =IFERROR(__xludf.DUMMYFUNCTION("""COMPUTED_VALUE"""),5350.500000000001) -> 5350.5 | P16: =IFERROR(__xludf.DUMMYFUNCTION("""COMPUTED_VALUE"""),"ETD") -> ETD | Q16: =IFERROR(__xludf.DUMMYFUNCTION("""COMPUTED_VALUE"""),"NO ECAC") -> NO ECAC
A17: =IFERROR(__xludf.DUMMYFUNCTION("""COMPUTED_VALUE"""),"QTR68R") -> QTR68R | B17: =IFERROR(__xludf.DUMMYFUNCTION("""COMPUTED_VALUE"""),"B789") -> B789 | C17: =IFERROR(__xludf.DUMMYFUNCTION("""COMPUTED_VALUE"""),"OTHH") -> OTHH | D17: =IFERROR(__xludf.DUMMYFUNCTION("""COMPUTED_VALUE"""),"LEBL") -> LEBL | E17: =IFERROR(__xludf.DUMMYFUNCTION("""COMPUTED_VALUE"""),"A7BHF") -> A7BHF | F17: =IFERROR(__xludf.DUMMYFUNCTION("""COMPUTED_VALUE"""),380.0) -> 380 | G17: =IFERROR(__xludf.DUMMYFUNCTION("""COMPUTED_VALUE"""),0.9548611111111112) -> 0.95486111 | H17: =IFERROR(__xludf.DUMMYFUNCTION("""COMPUTED_VALUE"""),10.0) -> 10 | I17: =IFERROR(__xludf.DUMMYFUNCTION("""COMPUTED_VALUE"""),0.2048611111111111) -> 0.20486111 | J17: =IFERROR(__xludf.DUMMYFUNCTION("""COMPUTED_VALUE"""),"B") -> B | K17: =IFERROR(__xludf.DUMMYFUNCTION("""COMPUTED_VALUE"""),284.0) -> 284 | L17: =IFERROR(__xludf.DUMMYFUNCTION("""COMPUTED_VALUE"""),0.25) -> 0.25 | M17: =IFERROR(__xludf.DUMMYFUNCTION("""COMPUTED_VALUE"""),0.23034722222222223) -> 0.23034722 | O17: =IFERROR(__xludf.DUMMYFUNCTION("""COMPUTED_VALUE"""),4975.5) -> 4975.5 | P17: =IFERROR(__xludf.DUMMYFUNCTION("""COMPUTED_VALUE"""),"QTR") -> QTR | Q17: =IFERROR(__xludf.DUMMYFUNCTION("""COMPUTED_VALUE"""),"NO ECAC") -> NO ECAC
A18: =IFERROR(__xludf.DUMMYFUNCTION("""COMPUTED_VALUE"""),"DAL250") -> DAL250 | B18: =IFERROR(__xludf.DUMMYFUNCTION("""COMPUTED_VALUE"""),"A339") -> A339 | C18: =IFERROR(__xludf.DUMMYFUNCTION("""COMPUTED_VALUE"""),"KBOS") -> KBOS | D18: =IFERROR(__xludf.DUMMYFUNCTION("""COMPUTED_VALUE"""),"LEBL") -> LEBL | E18: =IFERROR(__xludf.DUMMYFUNCTION("""COMPUTED_VALUE"""),"N401DZ") -> N401DZ | F18: =IFERROR(__xludf.DUMMYFUNCTION("""COMPUTED_VALUE"""),410.0) -> 410 | G18: =IFERROR(__xludf.DUMMYFUNCTION("""COMPUTED_VALUE"""),0.9298611111111111) -> 0.92986111 | H18: =IFERROR(__xludf.DUMMYFUNCTION("""COMPUTED_VALUE"""),19.0) -> 19 | I18: =IFERROR(__xludf.DUMMYFUNCTION("""COMPUTED_VALUE"""),0.21180555555555555) -> 0.21180556 | J18: =IFERROR(__xludf.DUMMYFUNCTION("""COMPUTED_VALUE"""),"B") -> B | K18: =IFERROR(__xludf.DUMMYFUNCTION("""COMPUTED_VALUE"""),281.0) -> 281 | L18: =IFERROR(__xludf.DUMMYFUNCTION("""COMPUTED_VALUE"""),0.28194444444444444) -> 0.28194444 | M18: =IFERROR(__xludf.DUMMYFUNCTION("""COMPUTED_VALUE"""),0.25604166666666667) -> 0.25604167 | O18: =IFERROR(__xludf.DUMMYFUNCTION("""COMPUTED_VALUE"""),5530.5) -> 5530.5 | P18: =IFERROR(__xludf.DUMMYFUNCTION("""COMPUTED_VALUE"""),"DAL") -> DAL | Q18: =IFERROR(__xludf.DUMMYFUNCTION("""COMPUTED_VALUE"""),"NO ECAC") -> NO ECAC
A19: =IFERROR(__xludf.DUMMYFUNCTION("""COMPUTED_VALUE"""),"RYR77ZB") -> RYR77ZB | B19: =IFERROR(__xludf.DUMMYFUNCTION("""COMPUTED_VALUE"""),"B738") -> B738 | C19: =IFERROR(__xludf.DUMMYFUNCTION("""COMPUTED_VALUE"""),"LEMG") -> LEMG | D19: =IFERROR(__xludf.DUMMYFUNCTION("""COMPUTED_VALUE"""),"LEBL") -> LEBL | E19: =IFERROR(__xludf.DUMMYFUNCTION("""COMPUTED_VALUE"""),"EIEFG") -> EIEFG | F19: =IFERROR(__xludf.DUMMYFUNCTION("""COMPUTED_VALUE"""),380.0) -> 380 | G19: =IFERROR(__xludf.DUMMYFUNCTION("""COMPUTED_VALUE"""),0.16597222222222222) -> 0.16597222 | H19: =IFERROR(__xludf.DUMMYFUNCTION("""COMPUTED_VALUE"""),12.0) -> 12 | I19: =IFERROR(__xludf.DUMMYFUNCTION("""COMPUTED_VALUE"""),0.2152777777777778) -> 0.21527778 | J19: =IFERROR(__xludf.DUMMYFUNCTION("""COMPUTED_VALUE"""),"D") -> D | K19: =IFERROR(__xludf.DUMMYFUNCTION("""COMPUTED_VALUE"""),184.0) -> 184 | L19: =IFERROR(__xludf.DUMMYFUNCTION("""COMPUTED_VALUE"""),0.049305555555555575) -> 0.049305556 | M19: =IFERROR(__xludf.DUMMYFUNCTION("""COMPUTED_VALUE"""),0.028263888888888908) -> 0.028263889 | O19: =IFERROR(__xludf.DUMMYFUNCTION("""COMPUTED_VALUE"""),563.016666666667) -> 563.01667 | P19: =IFERROR(__xludf.DUMMYFUNCTION("""COMPUTED_VALUE"""),"RYR") -> RYR | Q19: =IFERROR(__xludf.DUMMYFUNCTION("""COMPUTED_VALUE"""),"ECAC") -> ECAC
A20: =IFERROR(__xludf.DUMMYFUNCTION("""COMPUTED_VALUE"""),"CCA577") -> CCA577 | B20: =IFERROR(__xludf.DUMMYFUNCTION("""COMPUTED_VALUE"""),"A359") -> A359 | C20: =IFERROR(__xludf.DUMMYFUNCTION("""COMPUTED_VALUE"""),"ZSPD") -> ZSPD | D20: =IFERROR(__xludf.DUMMYFUNCTION("""COMPUTED_VALUE"""),"LEBL") -> LEBL | E20: =IFERROR(__xludf.DUMMYFUNCTION("""COMPUTED_VALUE"""),"B1085") -> B1085 | F20: =IFERROR(__xludf.DUMMYFUNCTION("""COMPUTED_VALUE"""),390.0) -> 390 | G20: =IFERROR(__xludf.DUMMYFUNCTION("""COMPUTED_VALUE"""),0.7013888888888888) -> 0.70138889 | H20: =IFERROR(__xludf.DUMMYFUNCTION("""COMPUTED_VALUE"""),10.0) -> 10 | I20: =IFERROR(__xludf.DUMMYFUNCTION("""COMPUTED_VALUE"""),0.2152777777777778) -> 0.21527778 | J20: =IFERROR(__xludf.DUMMYFUNCTION("""COMPUTED_VALUE"""),"B") -> B | K20: =IFERROR(__xludf.DUMMYFUNCTION("""COMPUTED_VALUE"""),297.0) -> 297 | L20: =IFERROR(__xludf.DUMMYFUNCTION("""COMPUTED_VALUE"""),0.513888888888889) -> 0.51388889 | M20: =IFERROR(__xludf.DUMMYFUNCTION("""COMPUTED_VALUE"""),0.4942361111111112) -> 0.49423611 | O20: =IFERROR(__xludf.DUMMYFUNCTION("""COMPUTED_VALUE"""),10675.500000000002) -> 10675.5 | P20: =IFERROR(__xludf.DUMMYFUNCTION("""COMPUTED_VALUE"""),"CCA") -> CCA | Q20: =IFERROR(__xludf.DUMMYFUNCTION("""COMPUTED_VALUE"""),"NO ECAC") -> NO ECAC
A21: =IFERROR(__xludf.DUMMYFUNCTION("""COMPUTED_VALUE"""),"EJU85AR") -> EJU85AR | B21: =IFERROR(__xludf.DUMMYFUNCTION("""COMPUTED_VALUE"""),"A20N") -> A20N | C21: =IFERROR(__xludf.DUMMYFUNCTION("""COMPUTED_VALUE"""),"LIMC") -> LIMC | D21: =IFERROR(__xludf.DUMMYFUNCTION("""COMPUTED_VALUE"""),"LEBL") -> LEBL | E21: =IFERROR(__xludf.DUMMYFUNCTION("""COMPUTED_VALUE"""),"OELSF") -> OELSF | F21: =IFERROR(__xludf.DUMMYFUNCTION("""COMPUTED_VALUE"""),290.0) -> 290 | G21: =IFERROR(__xludf.DUMMYFUNCTION("""COMPUTED_VALUE"""),0.17083333333333334) -> 0.17083333 | H21: =IFERROR(__xludf.DUMMYFUNCTION("""COMPUTED_VALUE"""),12.0) -> 12 | I21: =IFERROR(__xludf.DUMMYFUNCTION("""COMPUTED_VALUE"""),0.21875) -> 0.21875 | J21: =IFERROR(__xludf.DUMMYFUNCTION("""COMPUTED_VALUE"""),"D") -> D | K21: =IFERROR(__xludf.DUMMYFUNCTION("""COMPUTED_VALUE"""),180.0) -> 180 | L21: =IFERROR(__xludf.DUMMYFUNCTION("""COMPUTED_VALUE"""),0.04791666666666666) -> 0.047916667 | M21: =IFERROR(__xludf.DUMMYFUNCTION("""COMPUTED_VALUE"""),0.026874999999999996) -> 0.026875 | O21: =IFERROR(__xludf.DUMMYFUNCTION("""COMPUTED_VALUE"""),535.3499999999999) -> 535.35 | P21: =IFERROR(__xludf.DUMMYFUNCTION("""COMPUTED_VALUE"""),"EJU") -> EJU | Q21: =IFERROR(__xludf.DUMMYFUNCTION("""COMPUTED_VALUE"""),"ECAC") -> ECAC
A22: =IFERROR(__xludf.DUMMYFUNCTION("""COMPUTED_VALUE"""),"VLG64ZA") -> VLG64ZA | B22: =IFERROR(__xludf.DUMMYFUNCTION("""COMPUTED_VALUE"""),"A320") -> A320 | C22: =IFERROR(__xludf.DUMMYFUNCTION("""COMPUTED_VALUE"""),"LEPA") -> LEPA | D22: =IFERROR(__xludf.DUMMYFUNCTION("""COMPUTED_VALUE"""),"LEBL") -> LEBL | E22: =IFERROR(__xludf.DUMMYFUNCTION("""COMPUTED_VALUE"""),"ECMXP") -> ECMXP | F22: =IFERROR(__xludf.DUMMYFUNCTION("""COMPUTED_VALUE"""),180.0) -> 180 | G22: =IFERROR(__xludf.DUMMYFUNCTION("""COMPUTED_VALUE"""),0.20972222222222223) -> 0.20972222 | H22: =IFERROR(__xludf.DUMMYFUNCTION("""COMPUTED_VALUE"""),17.0) -> 17 | I22: =IFERROR(__xludf.DUMMYFUNCTION("""COMPUTED_VALUE"""),0.2222222222222222) -> 0.22222222 | J22: =IFERROR(__xludf.DUMMYFUNCTION("""COMPUTED_VALUE"""),"D") -> D | K22: =IFERROR(__xludf.DUMMYFUNCTION("""COMPUTED_VALUE"""),173.0) -> 173 | L22: =IFERROR(__xludf.DUMMYFUNCTION("""COMPUTED_VALUE"""),0.012499999999999983) -> 0.0125 | M22: =IFERROR(__xludf.DUMMYFUNCTION("""COMPUTED_VALUE"""),6.944444444444281E-4) -> 0.00069444444 | O22: =IFERROR(__xludf.DUMMYFUNCTION("""COMPUTED_VALUE"""),13.833333333333007) -> 13.833333 | P22: =IFERROR(__xludf.DUMMYFUNCTION("""COMPUTED_VALUE"""),"VLG") -> VLG | Q22: =IFERROR(__xludf.DUMMYFUNCTION("""COMPUTED_VALUE"""),"ECAC") -> ECAC
A23: =IFERROR(__xludf.DUMMYFUNCTION("""COMPUTED_VALUE"""),"RYR14DQ") -> RYR14DQ | B23: =IFERROR(__xludf.DUMMYFUNCTION("""COMPUTED_VALUE"""),"B38M") -> B38M | C23: =IFERROR(__xludf.DUMMYFUNCTION("""COMPUTED_VALUE"""),"LMML") -> LMML | D23: =IFERROR(__xludf.DUMMYFUNCTION("""COMPUTED_VALUE"""),"LEBL") -> LEBL | E23: =IFERROR(__xludf.DUMMYFUNCTION("""COMPUTED_VALUE"""),"EIIJL") -> EIIJL | F23: =IFERROR(__xludf.DUMMYFUNCTION("""COMPUTED_VALUE"""),360.0) -> 360 | G23: =IFERROR(__xludf.DUMMYFUNCTION("""COMPUTED_VALUE"""),0.1701388888888889) -> 0.17013889 | H23: =IFERROR(__xludf.DUMMYFUNCTION("""COMPUTED_VALUE"""),15.0) -> 15 | I23: =IFERROR(__xludf.DUMMYFUNCTION("""COMPUTED_VALUE"""),0.22916666666666666) -> 0.22916667 | J23: =IFERROR(__xludf.DUMMYFUNCTION("""COMPUTED_VALUE"""),"D") -> D | K23: =IFERROR(__xludf.DUMMYFUNCTION("""COMPUTED_VALUE"""),186.0) -> 186 | L23: =IFERROR(__xludf.DUMMYFUNCTION("""COMPUTED_VALUE"""),0.05902777777777776) -> 0.059027778 | M23: =IFERROR(__xludf.DUMMYFUNCTION("""COMPUTED_VALUE"""),0.03590277777777776) -> 0.035902778 | O23: =IFERROR(__xludf.DUMMYFUNCTION("""COMPUTED_VALUE"""),715.183333333333) -> 715.18333 | P23: =IFERROR(__xludf.DUMMYFUNCTION("""COMPUTED_VALUE"""),"RYR") -> RYR | Q23: =IFERROR(__xludf.DUMMYFUNCTION("""COMPUTED_VALUE"""),"ECAC") -> ECAC
A24: =IFERROR(__xludf.DUMMYFUNCTION("""COMPUTED_VALUE"""),"VLG1XG") -> VLG1XG | B24: =IFERROR(__xludf.DUMMYFUNCTION("""COMPUTED_VALUE"""),"A320") -> A320 | C24: =IFERROR(__xludf.DUMMYFUNCTION("""COMPUTED_VALUE"""),"LEIB") -> LEIB | D24: =IFERROR(__xludf.DUMMYFUNCTION("""COMPUTED_VALUE"""),"LEBL") -> LEBL | E24: =IFERROR(__xludf.DUMMYFUNCTION("""COMPUTED_VALUE"""),"ECLUN") -> ECLUN | F24: =IFERROR(__xludf.DUMMYFUNCTION("""COMPUTED_VALUE"""),180.0) -> 180 | G24: =IFERROR(__xludf.DUMMYFUNCTION("""COMPUTED_VALUE"""),0.21597222222222223) -> 0.21597222 | H24: =IFERROR(__xludf.DUMMYFUNCTION("""COMPUTED_VALUE"""),7.0) -> 7 | I24: =IFERROR(__xludf.DUMMYFUNCTION("""COMPUTED_VALUE"""),0.2361111111111111) -> 0.23611111 | J24: =IFERROR(__xludf.DUMMYFUNCTION("""COMPUTED_VALUE"""),"D") -> D | K24: =IFERROR(__xludf.DUMMYFUNCTION("""COMPUTED_VALUE"""),173.0) -> 173 | L24: =IFERROR(__xludf.DUMMYFUNCTION("""COMPUTED_VALUE"""),0.020138888888888873) -> 0.020138889 | M24: =IFERROR(__xludf.DUMMYFUNCTION("""COMPUTED_VALUE"""),0.002569444444444428) -> 0.0025694444 | O24: =IFERROR(__xludf.DUMMYFUNCTION("""COMPUTED_VALUE"""),51.183333333333) -> 51.183333 | P24: =IFERROR(__xludf.DUMMYFUNCTION("""COMPUTED_VALUE"""),"VLG") -> VLG | Q24: =IFERROR(__xludf.DUMMYFUNCTION("""COMPUTED_VALUE"""),"ECAC") -> ECAC
A25: =IFERROR(__xludf.DUMMYFUNCTION("""COMPUTED_VALUE"""),"VLG4CG") -> VLG4CG | B25: =IFERROR(__xludf.DUMMYFUNCTION("""COMPUTED_VALUE"""),"A320") -> A320 | C25: =IFERROR(__xludf.DUMMYFUNCTION("""COMPUTED_VALUE"""),"LEAL") -> LEAL | D25: =IFERROR(__xludf.DUMMYFUNCTION("""COMPUTED_VALUE"""),"LEBL") -> LEBL | E25: =IFERROR(__xludf.DUMMYFUNCTION("""COMPUTED_VALUE"""),"ECMVD") -> ECMVD | F25: =IFERROR(__xludf.DUMMYFUNCTION("""COMPUTED_VALUE"""),260.0) -> 260 | G25: =IFERROR(__xludf.DUMMYFUNCTION("""COMPUTED_VALUE"""),0.20416666666666666) -> 0.20416667 | H25: =IFERROR(__xludf.DUMMYFUNCTION("""COMPUTED_VALUE"""),9.0) -> 9 | I25: =IFERROR(__xludf.DUMMYFUNCTION("""COMPUTED_VALUE"""),0.2361111111111111) -> 0.23611111 | J25: =IFERROR(__xludf.DUMMYFUNCTION("""COMPUTED_VALUE"""),"D") -> D | K25: =IFERROR(__xludf.DUMMYFUNCTION("""COMPUTED_VALUE"""),173.0) -> 173 | L25: =IFERROR(__xludf.DUMMYFUNCTION("""COMPUTED_VALUE"""),0.03194444444444444) -> 0.031944444 | M25: =IFERROR(__xludf.DUMMYFUNCTION("""COMPUTED_VALUE"""),0.012986111111111106) -> 0.012986111 | O25: =IFERROR(__xludf.DUMMYFUNCTION("""COMPUTED_VALUE"""),258.6833333333332) -> 258.68333 | P25: =IFERROR(__xludf.DUMMYFUNCTION("""COMPUTED_VALUE"""),"VLG") -> VLG | Q25: =IFERROR(__xludf.DUMMYFUNCTION("""COMPUTED_VALUE"""),"ECAC") -> ECAC
A26: =IFERROR(__xludf.DUMMYFUNCTION("""COMPUTED_VALUE"""),"WMT262") -> WMT262 | B26: =IFERROR(__xludf.DUMMYFUNCTION("""COMPUTED_VALUE"""),"A21N") -> A21N | C26: =IFERROR(__xludf.DUMMYFUNCTION("""COMPUTED_VALUE"""),"LROP") -> LROP | D26: =IFERROR(__xludf.DUMMYFUNCTION("""COMPUTED_VALUE"""),"LEBL") -> LEBL | E26: =IFERROR(__xludf.DUMMYFUNCTION("""COMPUTED_VALUE"""),"9HWAY") -> 9HWAY | F26: =IFERROR(__xludf.DUMMYFUNCTION("""COMPUTED_VALUE"""),350.0) -> 350 | G26: =IFERROR(__xludf.DUMMYFUNCTION("""COMPUTED_VALUE"""),0.13194444444444445) -> 0.13194444 | H26: =IFERROR(__xludf.DUMMYFUNCTION("""COMPUTED_VALUE"""),10.0) -> 10 | I26: =IFERROR(__xludf.DUMMYFUNCTION("""COMPUTED_VALUE"""),0.23958333333333334) -> 0.23958333 | J26: =IFERROR(__xludf.DUMMYFUNCTION("""COMPUTED_VALUE"""),"D") -> D | K26: =IFERROR(__xludf.DUMMYFUNCTION("""COMPUTED_VALUE"""),200.0) -> 200 | L26: =IFERROR(__xludf.DUMMYFUNCTION("""COMPUTED_VALUE"""),0.1076388888888889) -> 0.10763889 | M26: =IFERROR(__xludf.DUMMYFUNCTION("""COMPUTED_VALUE"""),0.08798611111111111) -> 0.087986111 | O26: =IFERROR(__xludf.DUMMYFUNCTION("""COMPUTED_VALUE"""),1752.6833333333334) -> 1752.6833 | P26: =IFERROR(__xludf.DUMMYFUNCTION("""COMPUTED_VALUE"""),"WMT") -> WMT | Q26: =IFERROR(__xludf.DUMMYFUNCTION("""COMPUTED_VALUE"""),"ECAC") -> ECAC
A27: =IFERROR(__xludf.DUMMYFUNCTION("""COMPUTED_VALUE"""),"ACA822") -> ACA822 | B27: =IFERROR(__xludf.DUMMYFUNCTION("""COMPUTED_VALUE"""),"B77W") -> B77W | C27: =IFERROR(__xludf.DUMMYFUNCTION("""COMPUTED_VALUE"""),"CYUL") -> CYUL | D27: =IFERROR(__xludf.DUMMYFUNCTION("""COMPUTED_VALUE"""),"LEBL") -> LEBL | E27: =IFERROR(__xludf.DUMMYFUNCTION("""COMPUTED_VALUE"""),"CFIUL") -> CFIUL | F27: =IFERROR(__xludf.DUMMYFUNCTION("""COMPUTED_VALUE"""),370.0) -> 370 | G27: =IFERROR(__xludf.DUMMYFUNCTION("""COMPUTED_VALUE"""),0.9444444444444444) -> 0.94444444 | H27: =IFERROR(__xludf.DUMMYFUNCTION("""COMPUTED_VALUE"""),10.0) -> 10 | I27: =IFERROR(__xludf.DUMMYFUNCTION("""COMPUTED_VALUE"""),0.23958333333333334) -> 0.23958333 | J27: =IFERROR(__xludf.DUMMYFUNCTION("""COMPUTED_VALUE"""),"B") -> B | K27: =IFERROR(__xludf.DUMMYFUNCTION("""COMPUTED_VALUE"""),331.0) -> 331 | L27: =IFERROR(__xludf.DUMMYFUNCTION("""COMPUTED_VALUE"""),0.29513888888888895) -> 0.29513889 | M27: =IFERROR(__xludf.DUMMYFUNCTION("""COMPUTED_VALUE"""),0.2754861111111112) -> 0.27548611 | O27: =IFERROR(__xludf.DUMMYFUNCTION("""COMPUTED_VALUE"""),5950.500000000002) -> 5950.5 | P27: =IFERROR(__xludf.DUMMYFUNCTION("""COMPUTED_VALUE"""),"ACA") -> ACA | Q27: =IFERROR(__xludf.DUMMYFUNCTION("""COMPUTED_VALUE"""),"NO ECAC") -> NO ECAC
A28: =IFERROR(__xludf.DUMMYFUNCTION("""COMPUTED_VALUE"""),"CCA845") -> CCA845 | B28: =IFERROR(__xludf.DUMMYFUNCTION("""COMPUTED_VALUE"""),"A359") -> A359 | C28: =IFERROR(__xludf.DUMMYFUNCTION("""COMPUTED_VALUE"""),"ZBAA") -> ZBAA | D28: =IFERROR(__xludf.DUMMYFUNCTION("""COMPUTED_VALUE"""),"LEBL") -> LEBL | E28: =IFERROR(__xludf.DUMMYFUNCTION("""COMPUTED_VALUE"""),"B307C") -> B307C | F28: =IFERROR(__xludf.DUMMYFUNCTION("""COMPUTED_VALUE"""),390.0) -> 390 | G28: =IFERROR(__xludf.DUMMYFUNCTION("""COMPUTED_VALUE"""),0.7916666666666666) -> 0.79166667 | H28: =IFERROR(__xludf.DUMMYFUNCTION("""COMPUTED_VALUE"""),10.0) -> 10 | I28: =IFERROR(__xludf.DUMMYFUNCTION("""COMPUTED_VALUE"""),0.2465277777777778) -> 0.24652778 | J28: =IFERROR(__xludf.DUMMYFUNCTION("""COMPUTED_VALUE"""),"B") -> B | K28: =IFERROR(__xludf.DUMMYFUNCTION("""COMPUTED_VALUE"""),297.0) -> 297 | L28: =IFERROR(__xludf.DUMMYFUNCTION("""COMPUTED_VALUE"""),0.45486111111111116) -> 0.45486111 | M28: =IFERROR(__xludf.DUMMYFUNCTION("""COMPUTED_VALUE"""),0.4352083333333334) -> 0.43520833 | O28: =IFERROR(__xludf.DUMMYFUNCTION("""COMPUTED_VALUE"""),9400.500000000002) -> 9400.5 | P28: =IFERROR(__xludf.DUMMYFUNCTION("""COMPUTED_VALUE"""),"CCA") -> CCA | Q28: =IFERROR(__xludf.DUMMYFUNCTION("""COMPUTED_VALUE"""),"NO ECAC") -> NO ECAC
A29: =IFERROR(__xludf.DUMMYFUNCTION("""COMPUTED_VALUE"""),"AEA14ZJ") -> AEA14ZJ | B29: =IFERROR(__xludf.DUMMYFUNCTION("""COMPUTED_VALUE"""),"B738") -> B738 | C29: =IFERROR(__xludf.DUMMYFUNCTION("""COMPUTED_VALUE"""),"LEPA") -> LEPA | D29: =IFERROR(__xludf.DUMMYFUNCTION("""COMPUTED_VALUE"""),"LEBL") -> LEBL | E29: =IFERROR(__xludf.DUMMYFUNCTION("""COMPUTED_VALUE"""),"ECLQX") -> ECLQX | F29: =IFERROR(__xludf.DUMMYFUNCTION("""COMPUTED_VALUE"""),180.0) -> 180 | G29: =IFERROR(__xludf.DUMMYFUNCTION("""COMPUTED_VALUE"""),0.22361111111111112) -> 0.22361111 | H29: =IFERROR(__xludf.DUMMYFUNCTION("""COMPUTED_VALUE"""),17.0) -> 17 | I29: =IFERROR(__xludf.DUMMYFUNCTION("""COMPUTED_VALUE"""),0.2465277777777778) -> 0.24652778 | J29: =IFERROR(__xludf.DUMMYFUNCTION("""COMPUTED_VALUE"""),"D") -> D | K29: =IFERROR(__xludf.DUMMYFUNCTION("""COMPUTED_VALUE"""),184.0) -> 184 | L29: =IFERROR(__xludf.DUMMYFUNCTION("""COMPUTED_VALUE"""),0.02291666666666667) -> 0.022916667 | M29: =IFERROR(__xludf.DUMMYFUNCTION("""COMPUTED_VALUE"""),0.011111111111111113) -> 0.011111111 | O29: =IFERROR(__xludf.DUMMYFUNCTION("""COMPUTED_VALUE"""),221.33333333333337) -> 221.33333 | P29: =IFERROR(__xludf.DUMMYFUNCTION("""COMPUTED_VALUE"""),"AEA") -> AEA | Q29: =IFERROR(__xludf.DUMMYFUNCTION("""COMPUTED_VALUE"""),"ECAC") -> ECAC
A30: =IFERROR(__xludf.DUMMYFUNCTION("""COMPUTED_VALUE"""),"VLG47KA") -> VLG47KA | B30: =IFERROR(__xludf.DUMMYFUNCTION("""COMPUTED_VALUE"""),"A320") -> A320 | C30: =IFERROR(__xludf.DUMMYFUNCTION("""COMPUTED_VALUE"""),"LFPO") -> LFPO | D30: =IFERROR(__xludf.DUMMYFUNCTION("""COMPUTED_VALUE"""),"LEBL") -> LEBL | E30: =IFERROR(__xludf.DUMMYFUNCTION("""COMPUTED_VALUE"""),"ECMFK") -> ECMFK | F30: =IFERROR(__xludf.DUMMYFUNCTION("""COMPUTED_VALUE"""),370.0) -> 370 | G30: =IFERROR(__xludf.DUMMYFUNCTION("""COMPUTED_VALUE"""),0.20208333333333334) -> 0.20208333 | H30: =IFERROR(__xludf.DUMMYFUNCTION("""COMPUTED_VALUE"""),16.0) -> 16 | I30: =IFERROR(__xludf.DUMMYFUNCTION("""COMPUTED_VALUE"""),0.2465277777777778) -> 0.24652778 | J30: =IFERROR(__xludf.DUMMYFUNCTION("""COMPUTED_VALUE"""),"D") -> D | K30: =IFERROR(__xludf.DUMMYFUNCTION("""COMPUTED_VALUE"""),173.0) -> 173 | L30: =IFERROR(__xludf.DUMMYFUNCTION("""COMPUTED_VALUE"""),0.04444444444444445) -> 0.044444444 | M30: =IFERROR(__xludf.DUMMYFUNCTION("""COMPUTED_VALUE"""),0.020625000000000004) -> 0.020625 | O30: =IFERROR(__xludf.DUMMYFUNCTION("""COMPUTED_VALUE"""),410.8500000000001) -> 410.85 | P30: =IFERROR(__xludf.DUMMYFUNCTION("""COMPUTED_VALUE"""),"VLG") -> VLG | Q30: =IFERROR(__xludf.DUMMYFUNCTION("""COMPUTED_VALUE"""),"ECAC") -> ECAC
A31: =IFERROR(__xludf.DUMMYFUNCTION("""COMPUTED_VALUE"""),"VLG26NX") -> VLG26NX | B31: =IFERROR(__xludf.DUMMYFUNCTION("""COMPUTED_VALUE"""),"A320") -> A320 | C31: =IFERROR(__xludf.DUMMYFUNCTION("""COMPUTED_VALUE"""),"LEMG") -> LEMG | D31: =IFERROR(__xludf.DUMMYFUNCTION("""COMPUTED_VALUE"""),"LEBL") -> LEBL | E31: =IFERROR(__xludf.DUMMYFUNCTION("""COMPUTED_VALUE"""),"ECMEA") -> ECMEA | F31: =IFERROR(__xludf.DUMMYFUNCTION("""COMPUTED_VALUE"""),360.0) -> 360 | G31: =IFERROR(__xludf.DUMMYFUNCTION("""COMPUTED_VALUE"""),0.19791666666666666) -> 0.19791667 | H31: =IFERROR(__xludf.DUMMYFUNCTION("""COMPUTED_VALUE"""),15.0) -> 15 | I31: =IFERROR(__xludf.DUMMYFUNCTION("""COMPUTED_VALUE"""),0.25) -> 0.25 | J31: =IFERROR(__xludf.DUMMYFUNCTION("""COMPUTED_VALUE"""),"D") -> D | K31: =IFERROR(__xludf.DUMMYFUNCTION("""COMPUTED_VALUE"""),173.0) -> 173 | L31: =IFERROR(__xludf.DUMMYFUNCTION("""COMPUTED_VALUE"""),0.05208333333333334) -> 0.052083333 | M31: =IFERROR(__xludf.DUMMYFUNCTION("""COMPUTED_VALUE"""),0.028958333333333343) -> 0.028958333 | O31: =IFERROR(__xludf.DUMMYFUNCTION("""COMPUTED_VALUE"""),576.8500000000003) -> 576.85 | P31: =IFERROR(__xludf.DUMMYFUNCTION("""COMPUTED_VALUE"""),"VLG") -> VLG | Q31: =IFERROR(__xludf.DUMMYFUNCTION("""COMPUTED_VALUE"""),"ECAC") -> ECAC
A32: =IFERROR(__xludf.DUMMYFUNCTION("""COMPUTED_VALUE"""),"VLG6HA") -> VLG6HA | B32: =IFERROR(__xludf.DUMMYFUNCTION("""COMPUTED_VALUE"""),"A320") -> A320 | C32: =IFERROR(__xludf.DUMMYFUNCTION("""COMPUTED_VALUE"""),"LEZL") -> LEZL | D32: =IFERROR(__xludf.DUMMYFUNCTION("""COMPUTED_VALUE"""),"LEBL") -> LEBL | E32: =IFERROR(__xludf.DUMMYFUNCTION("""COMPUTED_VALUE"""),"ECOKH") -> ECOKH | F32: =IFERROR(__xludf.DUMMYFUNCTION("""COMPUTED_VALUE"""),340.0) -> 340 | G32: =IFERROR(__xludf.DUMMYFUNCTION("""COMPUTED_VALUE"""),0.20069444444444445) -> 0.20069444 | H32: =IFERROR(__xludf.DUMMYFUNCTION("""COMPUTED_VALUE"""),10.0) -> 10 | I32: =IFERROR(__xludf.DUMMYFUNCTION("""COMPUTED_VALUE"""),0.25) -> 0.25 | J32: =IFERROR(__xludf.DUMMYFUNCTION("""COMPUTED_VALUE"""),"D") -> D | K32: =IFERROR(__xludf.DUMMYFUNCTION("""COMPUTED_VALUE"""),173.0) -> 173 | L32: =IFERROR(__xludf.DUMMYFUNCTION("""COMPUTED_VALUE"""),0.04930555555555555) -> 0.049305556 | M32: =IFERROR(__xludf.DUMMYFUNCTION("""COMPUTED_VALUE"""),0.029652777777777767) -> 0.029652778 | O32: =IFERROR(__xludf.DUMMYFUNCTION("""COMPUTED_VALUE"""),590.6833333333332) -> 590.68333 | P32: =IFERROR(__xludf.DUMMYFUNCTION("""COMPUTED_VALUE"""),"VLG") -> VLG | Q32: =IFERROR(__xludf.DUMMYFUNCTION("""COMPUTED_VALUE"""),"ECAC") -> ECAC
A33: =IFERROR(__xludf.DUMMYFUNCTION("""COMPUTED_VALUE"""),"VLG6XL") -> VLG6XL | B33: =IFERROR(__xludf.DUMMYFUNCTION("""COMPUTED_VALUE"""),"A320") -> A320 | C33: =IFERROR(__xludf.DUMMYFUNCTION("""COMPUTED_VALUE"""),"LEPA") -> LEPA | D33: =IFERROR(__xludf.DUMMYFUNCTION("""COMPUTED_VALUE"""),"LEBL") -> LEBL | E33: =IFERROR(__xludf.DUMMYFUNCTION("""COMPUTED_VALUE"""),"ECOGC") -> ECOGC | F33: =IFERROR(__xludf.DUMMYFUNCTION("""COMPUTED_VALUE"""),180.0) -> 180 | G33: =IFERROR(__xludf.DUMMYFUNCTION("""COMPUTED_VALUE"""),0.2375) -> 0.2375 | H33: =IFERROR(__xludf.DUMMYFUNCTION("""COMPUTED_VALUE"""),17.0) -> 17 | I33: =IFERROR(__xludf.DUMMYFUNCTION("""COMPUTED_VALUE"""),0.25) -> 0.25 | J33: =IFERROR(__xludf.DUMMYFUNCTION("""COMPUTED_VALUE"""),"D") -> D | K33: =IFERROR(__xludf.DUMMYFUNCTION("""COMPUTED_VALUE"""),173.0) -> 173 | L33: =IFERROR(__xludf.DUMMYFUNCTION("""COMPUTED_VALUE"""),0.012500000000000011) -> 0.0125 | M33: =IFERROR(__xludf.DUMMYFUNCTION("""COMPUTED_VALUE"""),6.944444444444559E-4) -> 0.00069444444 | O33: =IFERROR(__xludf.DUMMYFUNCTION("""COMPUTED_VALUE"""),13.833333333333561) -> 13.833333 | P33: =IFERROR(__xludf.DUMMYFUNCTION("""COMPUTED_VALUE"""),"VLG") -> VLG | Q33: =IFERROR(__xludf.DUMMYFUNCTION("""COMPUTED_VALUE"""),"ECAC") -> ECAC
A34: =IFERROR(__xludf.DUMMYFUNCTION("""COMPUTED_VALUE"""),"FIA511") -> FIA511 | B34: =IFERROR(__xludf.DUMMYFUNCTION("""COMPUTED_VALUE"""),"A320") -> A320 | C34: =IFERROR(__xludf.DUMMYFUNCTION("""COMPUTED_VALUE"""),"LUKK") -> LUKK | D34: =IFERROR(__xludf.DUMMYFUNCTION("""COMPUTED_VALUE"""),"LEBL") -> LEBL | E34: =IFERROR(__xludf.DUMMYFUNCTION("""COMPUTED_VALUE"""),"ER00008") -> ER00008 | F34: =IFERROR(__xludf.DUMMYFUNCTION("""COMPUTED_VALUE"""),360.0) -> 360 | G34: =IFERROR(__xludf.DUMMYFUNCTION("""COMPUTED_VALUE"""),0.11458333333333333) -> 0.11458333 | H34: =IFERROR(__xludf.DUMMYFUNCTION("""COMPUTED_VALUE"""),15.0) -> 15 | I34: =IFERROR(__xludf.DUMMYFUNCTION("""COMPUTED_VALUE"""),0.25) -> 0.25 | J34: =IFERROR(__xludf.DUMMYFUNCTION("""COMPUTED_VALUE"""),"D") -> D | K34: =IFERROR(__xludf.DUMMYFUNCTION("""COMPUTED_VALUE"""),173.0) -> 173 | L34: =IFERROR(__xludf.DUMMYFUNCTION("""COMPUTED_VALUE"""),0.13541666666666669) -> 0.13541667 | M34: =IFERROR(__xludf.DUMMYFUNCTION("""COMPUTED_VALUE"""),0.11229166666666668) -> 0.11229167 | O34: =IFERROR(__xludf.DUMMYFUNCTION("""COMPUTED_VALUE"""),2236.8500000000004) -> 2236.85 | P34: =IFERROR(__xludf.DUMMYFUNCTION("""COMPUTED_VALUE"""),"FIA") -> FIA | Q34: =IFERROR(__xludf.DUMMYFUNCTION("""COMPUTED_VALUE"""),"ECAC") -> ECAC
A35: =IFERROR(__xludf.DUMMYFUNCTION("""COMPUTED_VALUE"""),"RYR47WZ") -> RYR47WZ | B35: =IFERROR(__xludf.DUMMYFUNCTION("""COMPUTED_VALUE"""),"B38M") -> B38M | C35: =IFERROR(__xludf.DUMMYFUNCTION("""COMPUTED_VALUE"""),"EYVI") -> EYVI | D35: =IFERROR(__xludf.DUMMYFUNCTION("""COMPUTED_VALUE"""),"LEBL") -> LEBL | E35: =IFERROR(__xludf.DUMMYFUNCTION("""COMPUTED_VALUE"""),"SPRZK") -> SPRZK | F35: =IFERROR(__xludf.DUMMYFUNCTION("""COMPUTED_VALUE"""),380.0) -> 380 | G35: =IFERROR(__xludf.DUMMYFUNCTION("""COMPUTED_VALUE"""),0.12152777777777778) -> 0.12152778 | H35: =IFERROR(__xludf.DUMMYFUNCTION("""COMPUTED_VALUE"""),10.0) -> 10 | I35: =IFERROR(__xludf.DUMMYFUNCTION("""COMPUTED_VALUE"""),0.2534722222222222) -> 0.25347222 | J35: =IFERROR(__xludf.DUMMYFUNCTION("""COMPUTED_VALUE"""),"D") -> D | K35: =IFERROR(__xludf.DUMMYFUNCTION("""COMPUTED_VALUE"""),186.0) -> 186 | L35: =IFERROR(__xludf.DUMMYFUNCTION("""COMPUTED_VALUE"""),0.13194444444444442) -> 0.13194444 | M35: =IFERROR(__xludf.DUMMYFUNCTION("""COMPUTED_VALUE"""),0.11229166666666664) -> 0.11229167 | O35: =IFERROR(__xludf.DUMMYFUNCTION("""COMPUTED_VALUE"""),2236.8499999999995) -> 2236.85 | P35: =IFERROR(__xludf.DUMMYFUNCTION("""COMPUTED_VALUE"""),"RYR") -> RYR | Q35: =IFERROR(__xludf.DUMMYFUNCTION("""COMPUTED_VALUE"""),"ECAC") -> ECAC
